<?xml version="1.0" ?>
<robot name="arm">
  <link name="base_link"/>
  <link name="arm_a_link">
    <visual>
      <origin rpy="0 0 0" xyz="0 0 0"/>
      <geometry>
        <mesh filename="../meshes/arm_a_fix.glb"/>
      </geometry>
    </visual>
  </link>
  <link name="arm_b_link">
    <visual>
      <origin rpy="0 0 0" xyz="0 0 0"/>
      <geometry>
        <mesh filename="../meshes/arm_b_fix.glb"/>
      </geometry>
    </visual>
  </link>
  <link name="arm_c_link">
    <visual>
      <origin rpy="0 0 0" xyz="0 0 0"/>
      <geometry>
        <mesh filename="../meshes/arm_c_fix.glb"/>
      </geometry>
    </visual>
  </link>
  <link name="arm_d_link">
    <visual>
      <origin rpy="0 0 0" xyz="0 0 0"/>
      <geometry>
        <mesh filename="../meshes/arm_d_fix.glb"/>
      </geometry>
    </visual>
  </link>
  <link name="arm_e_link">
    <visual>
      <origin rpy="0 0 0" xyz="0 0 0"/>
      <geometry>
        <mesh filename="../meshes/arm_e_fix.glb"/>
      </geometry>
    </visual>
  </link>
  <link name="arm_gripper_link">
    <visual>
      <origin xyz="0 0 0" rpy="0 0 0"/>
      <geometry>
        <mesh filename="../meshes/arm_gripper_fix.glb"/>
      </geometry>
    </visual>
  </link>
  <joint name="base_to_arm_a" type="prismatic">
    <origin rpy="0 0 0" xyz="0 0 0"/>
    <parent link="base_link"/>
    <child link="arm_a_link"/>
    <axis xyz="0 -1 0"/>
    <limit lower="0" upper="40"/>
  </joint>
  <joint name="arm_a_to_arm_b" type="revolute">
    <origin rpy="0 0 0" xyz="3.4348 -0.0005 4.9028"/>
    <parent link="arm_a_link"/>
    <child link="arm_b_link"/>
    <axis xyz="0 1 0"/>
    <limit lower="-0.7853981875" upper="0"/>
  </joint>
  <joint name="arm_b_to_arm_c" type="revolute">
    <origin rpy="0 0 0" xyz="53.4363 0.0005 0.9052"/>
    <parent link="arm_b_link"/>
    <child link="arm_c_link"/>
    <axis xyz="0 1 0"/>
    <limit lower="-0.959931" upper="2.87979"/>
  </joint>
  <joint name="arm_c_to_arm_d" type="revolute">
    <origin rpy="0 0 0" xyz="54.6037 0 8.8594"/>
    <parent link="arm_c_link"/>
    <child link="arm_d_link"/>
    <axis xyz="0 1 0"/>
    <limit lower="-2.35619" upper="2.35619"/>
  </joint>
  <joint name="arm_d_to_arm_e" type="revolute">
    <origin rpy="0 0 0" xyz="4.488 0 0"/>
    <parent link="arm_d_link"/>
    <child link="arm_e_link"/>
    <axis xyz="1 0 0"/>
    <limit lower="-2.35619" upper="2.35619"/>
  </joint>
  <joint name="gripper_link" type="prismatic">
    <origin rpy="1.570796 0 0" xyz="0.0875 0 0"/>
    <parent link="arm_e_link"/>
    <child link="arm_gripper_link"/>
    <axis xyz="0 1 0"/>
    <limit lower="0" upper="8"/>
  </joint>
</robot>
