<?xml version="1.0" ?>
<robot name="left_suspension">
  <link name="base_link"/>
  <link name="left_rocker_link">
    <visual>
      <geometry>
        <mesh filename="../meshes/rover_left_rocker_fix.glb"/>
      </geometry>
    </visual>
  </link>
  <link name="left_bogie_link">
    <visual>
      <geometry>
        <mesh filename="../meshes/rover_left_bogie_fix.glb"/>
      </geometry>
    </visual>
  </link>
  <link name="front_left_wheel_link">
    <visual>
      <origin rpy="0 0 0" xyz="0 0 0"/>
      <geometry>
        <mesh filename="../meshes/rover_left_wheel_fix.glb"/>
      </geometry>
    </visual>
  </link>
  <link name="center_left_wheel_link">
    <visual>
      <origin rpy="0 0 0" xyz="0 0 0"/>
      <geometry>
        <mesh filename="../meshes/rover_left_wheel_fix.glb"/>
      </geometry>
    </visual>
  </link>
  <link name="back_left_wheel_link">
    <visual>
      <origin rpy="0 0 0" xyz="0 0 0"/>
      <geometry>
        <mesh filename="../meshes/rover_left_wheel_fix.glb"/>
      </geometry>
    </visual>
  </link>
  <joint name="base_to_rocker" type="fixed">
    <parent link="base_link"/>
    <child link="left_rocker_link"/>
    <origin rpy="0 0 0" xyz="0 0 0"/>
  </joint>
  <joint name="left_rocker_to_left_bogie" type="revolute">
    <parent link="left_rocker_link"/>
    <child link="left_bogie_link"/>
    <origin rpy="0 0 0" xyz="19.8948 0.0226 -13.8674"/>
    <axis xyz="0 1 0"/>
    <limit lower="-0.349066" upper="0.349066"/>
  </joint>
  <joint name="left_bogie_to_front_left_wheel" type="continuous">
    <parent link="left_bogie_link"/>
    <child link="front_left_wheel_link"/>
    <origin xyz="21.5233 9 -14.7933"/>
    <axis xyz="0 1 0"/>
    <limit lower="-10" upper="10"/>
  </joint>
  <joint name="left_bogie_to_center_left_wheel" type="continuous">
    <parent link="left_bogie_link"/>
    <child link="center_left_wheel_link"/>
    <origin xyz="-17.3532 9 -14.7659"/>
    <axis xyz="0 1 0"/>
    <limit lower="-10" upper="10"/>
  </joint>
  <joint name="left_rocker_to_back_left_wheel" type="continuous">
    <parent link="left_rocker_link"/>
    <child link="back_left_wheel_link"/>
    <origin xyz="-41.7094 9 -28.513 "/>
    <axis xyz="0 1 0"/>
    <limit lower="-10" upper="10"/>
  </joint>
</robot>
